Workbook

Sheet Summary
A1: Zotero Group Collection Audit
A2: SCIE 4403 Lit Review / Lit Review Papers | audit date: 2026-09-02
A4: Collection records | B4: =COUNTA(Inventory!$H$2:$H$19) -> 18 | D4: Audit boundary
A5: Unique bibliographic records | B5: =B4-B8 -> 17 | D5: Stage 7 is complete: the review is organised into six argument-led sections and 19 planned synthesis steps.
A6: PDFs locally available | B6: =COUNTIF(Inventory!$M$2:$M$19,"AVAILABLE") -> 18 | D6: The sequence moves from evidence rules to westward/eastward movement, regional mechanisms, language interpretation, limits and final synthesis.
A7: PDFs readable | B7: =COUNTIF(Inventory!$N$2:$N$19,"VALID") -> 18 | D7: Every planned claim is linked to existing studies and evidence pointers, with earlier, target-period and later evidence kept distinct.
A8: Duplicate excess records | B8: =COUNTIF(Inventory!$Q$2:$Q$19,"DUPLICATE") -> 1 | D8: This is an outline only; no review prose has been drafted. Stage 8 will begin only if drafting is explicitly requested.
A9: Records missing DOI | B9: =COUNTBLANK(Inventory!$F$2:$F$19) -> 0
A10: Unique title/abstract records screened | B10: =COUNTIF('Screening Decisions'!$F$2:$F$19,"YES") -> 17 | D10: Key audit finding
A11: Group records retained | B11: =COUNTIFS('Screening Decisions'!$F$2:$F$19,"YES",'Screening Decisions'!$G$2:$G$19,"INCLUDE") -> 17 | D11: Strongest convergence: multi-stage Yamnaya formation and rapid westward dispersal around 3300–3000 BCE.
A12: Full texts assessed | B12: =COUNTA('Evidence Extraction'!$B$2:$B$16) -> 15 | D12: Eastward Afanasievo-related movement is supported, but the intermediate route remains more sparsely sampled.
A13: Studies in cross-study synthesis | B13: =COUNTA('Synthesis Table'!$A$2:$A$16) -> 15 | D13: Regional studies consistently qualify a uniform replacement model through admixture, sex bias and cultural transmission.
A14: My-section background only | B14: =COUNTIF('Screening Decisions'!$I$2:$I$19,"BACKGROUND ONLY") -> 2 | D14: The principal language gap is the absence of direct linguistic evidence: demographic compatibility is not proof of speech.
A15: Full-text exclusions | B15: =COUNTIF('Screening Decisions'!$O$2:$O$19,"EXCLUDE") -> 0
A16: Areas of agreement | B16: =COUNTIF('Agreements & Gaps'!$A$5:$A$24,"AGREEMENT") -> 6
A17: Tensions / disagreements | B17: =COUNTIF('Agreements & Gaps'!$A$5:$A$24,"TENSION") -> 7
A18: Evidence gaps | B18: =COUNTIF('Agreements & Gaps'!$A$5:$A$24,"GAP") -> 7
A19: Major outline sections | B19: =MAX('Argument Outline'!$B$5:$B$23) -> 6
A20: Argument steps | B20: =COUNTA('Argument Outline'!$A$5:$A$23) -> 19

Sheet Inventory
A1: Record # | B1: Creator(s) | C1: Year | D1: Title | E1: Publication | F1: DOI | G1: URL | H1: Zotero Item Key | I1: BibTeX Key | J1: Source Catalog | K1: Added to Zotero | L1: PDF Attachment Key | M1: PDF Availability | N1: PDF Readability | O1: PDF Pages | P1: PDF Size (bytes) | Q1: Duplicate Status | R1: Group Relevance | S1: My Section Relevance | T1: Audit Notes
A2: 1 | B2: Wong et al. | C2: 2017 | D2: Reconstructing genetic history of Siberian and Northeastern European populations | E2: Genome Research | F2: 10.1101/gr.202945.115 | H2: CEFW5MDT | I2: wong_reconstructing_2017 | J2: Clarivate Analytics Web of Science | K2: 46266.39 | L2: BWE7BMJ5 | M2: AVAILABLE | N2: VALID | O2: 15 | P2: 2799848 | Q2: UNIQUE | R2: INCLUDE | S2: INCLUDE - MIGRATION
A3: 2 | B3: Chintalapati et al. | C3: 2022 | D3: The spatiotemporal patterns of major human admixture events during the European Holocene | E3: eLife | F3: 10.7554/eLife.77625 | G3: https://elifesciences.org/articles/77625 | H3: EIBGSQF3 | I3: chintalapati_spatiotemporal_2022 | J3: Clarivate Analytics Web of Science | K3: 46266.39 | L3: H3X8UPU5 | M3: AVAILABLE | N3: VALID | O3: 43 | P3: 8757452 | Q3: UNIQUE | R3: INCLUDE | S3: INCLUDE - MIGRATION + LANGUAGE
A4: 3 | B4: Wang et al. | C4: 2021 | D4: Genomic insights into the formation of human populations in East Asia | E4: Nature | F4: 10.1038/s41586-021-03336-2 | G4: https://www.nature.com/articles/s41586-021-03336-2 | H4: 4IUR2RSU | I4: wang_genomic_2021 | J4: www.nature.com | K4: 46266.389 | L4: Y6XQYYTF | M4: AVAILABLE | N4: VALID | O4: 25 | P4: 20139128 | Q4: UNIQUE | R4: INCLUDE | S4: INCLUDE - MIGRATION + LANGUAGE | T4: A bibliographic match exists outside this collection as unfiled group item IVVVT6WZ; see Flag Register.
A5: 4 | B5: Librado et al. | C5: 2021 | D5: The origins and spread of domestic horses from the Western Eurasian steppes | E5: Nature | F5: 10.1038/s41586-021-04018-9 | G5: https://www.nature.com/articles/s41586-021-04018-9 | H5: QD6IY2HJ | I5: librado_origins_2021 | J5: Clarivate Analytics Web of Science | K5: 46266.388 | L5: BVIH8K6B | M5: AVAILABLE | N5: VALID | O5: 24 | P5: 12033106 | Q5: UNIQUE | R5: INCLUDE | S5: BACKGROUND ONLY
A6: 5 | B6: Scorrano et al. | C6: 2021 | D6: The genetic and cultural impact of the Steppe migration into Europe. | E6: Annals of Human Biology | F6: 10.1080/03014460.2021.1942984 | G6: https://research.ebsco.com/plink/da3fd0bc-0e84-3874-9253-4d17249125a6 | H6: 24A5ALRY | I6: scorrano_genetic_2021 | J6: EBSCOhost | K6: 46266.387 | L6: 84LGCG9B | M6: AVAILABLE | N6: VALID | O6: 12 | P6: 2169520 | Q6: UNIQUE | R6: INCLUDE | S6: INCLUDE - MIGRATION
A7: 6 | B7: Linderholm et al. | C7: 2020 | D7: Corded Ware cultural complexity uncovered using genomic and isotopic analysis from south-eastern Poland | E7: Scientific Reports | F7: 10.1038/s41598-020-63138-w | G7: https://www.nature.com/articles/s41598-020-63138-w | H7: Z6RYK2BV | I7: linderholm_corded_2020 | J7: Clarivate Analytics Web of Science | K7: 46266.386 | L7: SRTBVJNI | M7: AVAILABLE | N7: VALID | O7: 13 | P7: 1658130 | Q7: UNIQUE | R7: INCLUDE | S7: INCLUDE - MIGRATION
A8: 7 | B8: Lazaridis et al. | C8: 2025 | D8: The genetic origin of the Indo-Europeans | E8: Nature | F8: 10.1038/s41586-024-08531-5 | G8: https://www.nature.com/articles/s41586-024-08531-5 | H8: DHIHCURJ | I8: lazaridis_genetic_2025 | J8: www.nature.com | K8: 46266.386 | L8: WJTY96RM | M8: AVAILABLE | N8: VALID | O8: 29 | P8: 24839158 | Q8: DUPLICATE | R8: EXCLUDE | S8: EXCLUDE | T8: Exact duplicate of KZVYLCU9; DOI, title, citation key, PDF size, and SHA-256 match.
A9: 8 | B9: Furholt | C9: 2018 | D9: Massive Migrations? The Impact of Recent aDNA Studies on our View of Third Millennium Europe | E9: European Journal of Archaeology | F9: 10.1017/eaa.2017.43 | H9: 2DPCPNXM | I9: furholt_massive_2018 | J9: Clarivate Analytics Web of Science | K9: 46266.385 | L9: F3V38A6Z | M9: AVAILABLE | N9: VALID | O9: 33 | P9: 597318 | Q9: UNIQUE | R9: INCLUDE | S9: BACKGROUND ONLY
A10: 9 | B10: Tassi et al. | C10: 2017 | D10: Genome diversity in the Neolithic Globular Amphorae culture and the spread of Indo-European languages | E10: Proceedings of the Royal Society B: Biological Sciences | F10: 10.1098/rspb.2017.1540 | G10: https://doi.org/10.1098/rspb.2017.1540 | H10: Q2Y9FLYQ | I10: tassi_genome_2017 | J10: Silverchair | K10: 46266.384 | L10: XDF7EXQE | M10: AVAILABLE | N10: VALID | O10: 9 | P10: 1038667 | Q10: UNIQUE | R10: INCLUDE | S10: INCLUDE - MIGRATION + LANGUAGE | T10: Also has an HTML snapshot child attachment.
A11: 10 | B11: Ringbauer et al. | C11: 2024 | D11: Accurate detection of identity-by-descent segments in human ancient DNA | E11: Nature Genetics | F11: 10.1038/s41588-023-01582-w | G11: https://www.nature.com/articles/s41588-023-01582-w | H11: MVP4P8Z2 | I11: ringbauer_accurate_2024 | J11: www.nature.com | K11: 46266.384 | L11: 6MUTAXCN | M11: AVAILABLE | N11: VALID | O11: 28 | P11: 14557210 | Q11: UNIQUE | R11: INCLUDE | S11: INCLUDE - MIGRATION
A12: 11 | B12: Dzhaubermezov et al. | C12: 2026 | D12: Genomic history of the Caucasus: A systematic review and meta-analysis of ancient DNA studies | E12: BioSystems | F12: 10.1016/j.biosystems.2026.105906 | G12: https://www.sciencedirect.com/science/article/pii/S0303264726002169 | H12: 8LBVFX2C | I12: dzhaubermezov_genomic_2026 | J12: ScienceDirect | K12: 46256.231 | L12: A4979JQC | M12: AVAILABLE | N12: VALID | O12: 11 | P12: 6338020 | Q12: UNIQUE | R12: INCLUDE | S12: INCLUDE - MIGRATION | T12: Zotero publication date is 2026-10-01, later than the 2026-09-02 audit date; verify metadata before citation. Also has an HTML snapshot.
A13: 12 | B13: Lazaridis et al. | C13: 2025 | D13: The genetic origin of the Indo-Europeans | E13: Nature | F13: 10.1038/s41586-024-08531-5 | G13: https://www.nature.com/articles/s41586-024-08531-5 | H13: KZVYLCU9 | I13: lazaridis_genetic_2025 | J13: www.nature.com | K13: 46256.259 | L13: ZKCVIDCI | M13: AVAILABLE | N13: VALID | O13: 29 | P13: 24839158 | Q13: CANONICAL IN DUPLICATE SET | R13: INCLUDE | S13: INCLUDE - MIGRATION + LANGUAGE | T13: Earlier-added copy; exact duplicate of DHIHCURJ.
A14: 13 | B14: Nikitin et al. | C14: 2025 | D14: A genomic history of the North Pontic Region from the Neolithic to the Bronze Age | E14: Nature | F14: 10.1038/s41586-024-08372-2 | G14: https://www.nature.com/articles/s41586-024-08372-2 | H14: 9DJYHJ7E | I14: nikitin_genomic_2025 | J14: www.nature.com | K14: 46256.259 | L14: JTQ4LNEQ | M14: AVAILABLE | N14: VALID | O14: 19 | P14: 9250193 | Q14: UNIQUE | R14: INCLUDE | S14: INCLUDE - MIGRATION
A15: 14 | B15: Papac et al. | C15: 2021 | D15: Dynamic changes in genomic and social structures in third millennium BCE central Europe | E15: Science Advances | F15: 10.1126/sciadv.abi6941 | G15: https://pmc.ncbi.nlm.nih.gov/articles/PMC8386934/ | H15: U92TYDRN | I15: papac_dynamic_2021 | J15: PubMed Central | K15: 46256.258 | L15: 2NADC6DR | M15: AVAILABLE | N15: VALID | O15: 17 | P15: 2674771 | Q15: UNIQUE | R15: INCLUDE | S15: INCLUDE - MIGRATION | T15: Also has a linked catalog-page child attachment.
A16: 15 | B16: Mathieson et al. | C16: 2018 | D16: The genomic history of southeastern Europe | E16: Nature | F16: 10.1038/nature25778 | G16: https://www.nature.com/articles/nature25778 | H16: TTSVUEKS | I16: mathieson_genomic_2018 | J16: www.nature.com | K16: 46256.257 | L16: NAGVBZVU | M16: AVAILABLE | N16: VALID | O16: 17 | P16: 4355397 | Q16: UNIQUE | R16: INCLUDE | S16: INCLUDE - MIGRATION
A17: 16 | B17: Olalde et al. | C17: 2018 | D17: The Beaker phenomenon and the genomic transformation of northwest Europe | E17: Nature | F17: 10.1038/nature25738 | G17: https://www.nature.com/articles/nature25738 | H17: 2PL38PG4 | I17: olalde_beaker_2018 | J17: www.nature.com | K17: 46256.257 | L17: US52X4SZ | M17: AVAILABLE | N17: VALID | O17: 22 | P17: 5794715 | Q17: UNIQUE | R17: INCLUDE | S17: INCLUDE - MIGRATION
A18: 17 | B18: Allentoft et al. | C18: 2015 | D18: Population genomics of Bronze Age Eurasia | E18: Nature | F18: 10.1038/nature14507 | G18: https://www.nature.com/articles/nature14507 | H18: B2PLN5IB | I18: allentoft_population_2015 | J18: www.nature.com | K18: 46256.257 | L18: FVL6J4BR | M18: AVAILABLE | N18: VALID | O18: 17 | P18: 5513099 | Q18: UNIQUE | R18: INCLUDE | S18: INCLUDE - MIGRATION + LANGUAGE
A19: 18 | B19: Haak et al. | C19: 2015 | D19: Massive migration from the steppe was a source for Indo-European languages in Europe | E19: Nature | F19: 10.1038/nature14317 | G19: https://www.nature.com/articles/nature14317 | H19: 6ZNHJTYH | I19: haak_massive_2015 | J19: www.nature.com | K19: 46256.257 | L19: XINUIG5V | M19: AVAILABLE | N19: VALID | O19: 14 | P19: 8248715 | Q19: UNIQUE | R19: INCLUDE | S19: INCLUDE - MIGRATION + LANGUAGE

Sheet Flag Register
A1: Flag | B1: Status | C1: Collection Item(s) | D1: Related Item | E1: Evidence | F1: Effect on Counts | G1: Recommended Follow-up
A2: Within-collection duplicate | B2: CONFIRMED | C2: DHIHCURJ; KZVYLCU9 | E2: Same DOI, title, citation key and 24,839,158-byte PDF; attachment SHA-256 hashes are identical. | F2: 18 records; 17 unique bibliographic records. | G2: Keep one canonical record after the group confirms which Zotero item to retain. No deletion was performed.
A3: Unfiled group-library match | B3: REVIEW | C3: 4IUR2RSU | D3: IVVVT6WZ | E3: Same title and DOI. IVVVT6WZ is outside Lit Review Papers and its PDF hash differs from the collection copy. | F3: Not counted in the 18-record collection inventory. | G3: Inspect whether it is an alternate PDF/version before any merge or deletion.
A4: Publication-date metadata | B4: VERIFY | C4: 8LBVFX2C | E4: Zotero date is 2026-10-01, which is later than the audit date 2026-09-02. | F4: No change to inventory count. | G4: Verify the publication date before using the citation.
A5: Search provenance gap | B5: UNKNOWN | E5: Zero Zotero saved-search objects; no database-level result count, filters, fields, export file or confirmed search date found. | F5: Collection size cannot be used as the PRISMA identification count. | G5: Recover the original database/export log from the group if it exists.

Sheet Provenance
A1: Field | B1: Value | C1: Interpretation / constraint
A2: Audit date | B2: 2026-09-02 | C2: Australia/Perth
A3: Zotero group | B3: SCIE 4403 Lit Review | C3: Group library ID 6645071
A4: Zotero collection | B4: Lit Review Papers | C4: Collection key 62E8UWNY
A5: Collection records | B5: 18 | C5: Top-level journal-article records in the named collection
A6: Group top-level journal records | B6: 19 | C6: Includes one unfiled Wang et al. bibliographic match outside the collection
A7: Saved Zotero searches | B7: 0 | C7: No saved-search object is available to reconstruct database search settings
A8: Historical query | B8: ("Yamnaya" OR "Yamna culture") AND ("DNA" OR "aDNA" OR "ancient genomics") AND ("migration" OR "Indo-European") | C8: Preserved exactly from thesis-workflow/SKILL.md
A9: Database used | B9: UNKNOWN | C9: Source Catalog metadata is not proof of the database used for the historical search
A10: Search date | B10: UNKNOWN | C10: Zotero dateAdded timestamps are import dates, not verified search dates
A11: Fields searched | B11: UNKNOWN | C11: Not recoverable from Zotero collection metadata
A12: Filters | B12: UNKNOWN | C12: Not recoverable from Zotero collection metadata
A13: Records initially retrieved | B13: UNKNOWN | C13: Do not substitute the 18 Zotero records for this PRISMA number
A14: Export filename | B14: UNKNOWN | C14: No export file or search log was found in Zotero
A15: Screening status | B15: TITLE/ABSTRACT SCREENING COMPLETE | C15: 17 unique records screened; one exact duplicate removed before screening
A16: Full-text assessment | B16: FULL-TEXT ELIGIBILITY COMPLETE | C16: 15 primary candidates assessed from accessible PDFs; 15 included, 0 not retrieved and 0 excluded. Evidence and page/section pointers are stored in Evidence Extraction. The 2 background-only records were not part of this stage.
A17: Synthesis status | B17: COMPLETE | C17: Cross-study Synthesis Table and seven-theme/gap map completed from the 15 full-text evidence records; no new search and no review prose drafting.
A18: Theme identification status | B18: COMPLETE | C18: Stage 5 validated seven evidence-driven recurring themes from the 15 included full-text studies. All included studies are represented; no new search and no review drafting.
A19: Disagreement / gap status | B19: COMPLETE | C19: Stage 6 mapped six cross-study agreements, seven tensions/disagreements and seven literature-demonstrated gaps. Interpretive disagreement is separated from regional variation, model uncertainty and missing evidence; no new search or review drafting.
A20: Argument outline status | B20: COMPLETE — OUTLINE ONLY | C20: Stage 7 created a six-section, 19-step argument structure linked to the synthesis, disagreement/gap map and evidence records. No new search and no literature-review prose drafting.

Sheet Screening Decisions
A1: Record # | B1: Zotero Item Key | C1: Study | D1: Duplicate Status | E1: Evidence Used | F1: Title/Abstract Screened | G1: Group Relevance | H1: Group Decision Reason | I1: My Section Relevance | J1: My Section Decision Reason | K1: Language Relevance | L1: Chronological Role | M1: PDF Available | N1: My-Section Full-Text Path | O1: Full-Text Assessment | P1: Notes
A2: 1 | B2: CEFW5MDT | C2: Wong et al. (2017) | D2: UNIQUE | E2: Accessible full text | F2: YES | G2: INCLUDE | H2: Genetic history and admixture involving Yamnaya and northern Eurasian populations are relevant to the overall aDNA review. | I2: INCLUDE - MIGRATION | J2: Abstract reports Yamnaya-related admixture and ancient gene flow relevant to population movement; it makes no substantive Indo-European claim. | K2: BACKGROUND | L2: DIRECT / TARGET PERIOD | M2: YES | N2: ADVANCE | O2: INCLUDE - MIGRATION | P2: Full text supports inclusion as contextual migration evidence; ancient Yamnaya evidence is comparative rather than a direct migration transect.
A3: 2 | B3: EIBGSQF3 | C3: Chintalapati et al. (2022) | D3: UNIQUE | E3: Accessible full text | F3: YES | G3: INCLUDE | H3: Ancient-genomic dating reconstructs Steppe pastoralist ancestry and migration chronology. | I3: INCLUDE - MIGRATION + LANGUAGE | J3: Abstract addresses the timing and spread of Steppe ancestry across Europe and explicitly relates the findings to Indo-European language spread. | K3: EXPLICIT | L3: MIXED: EARLIER FORMATION + TARGET-PERIOD SPREAD | M3: YES | N3: ADVANCE | O3: INCLUDE - MIGRATION + LANGUAGE | P3: Full text assessed; direct demographic results and language interpretation are separated in Evidence Extraction.
A4: 3 | B4: 4IUR2RSU | C4: Wang et al. (2021) | D4: UNIQUE | E4: Accessible full text | F4: YES | G4: INCLUDE | H4: Genome-wide data address Eurasian population formation and Yamnaya-related ancestry in eastern Eurasia. | I4: INCLUDE - MIGRATION + LANGUAGE | J4: Abstract reports Yamnaya ancestry reaching western Mongolia after about 3000 BCE and explicitly proposes compatibility with proto-Tocharian dispersal. | K4: EXPLICIT | L4: DIRECT + LATER CONTINUATION | M4: YES | N4: ADVANCE | O4: INCLUDE - MIGRATION + LANGUAGE | P4: Full text assessed; proto-Tocharian is an author interpretation, not a genetic observation.
A5: 4 | B5: QD6IY2HJ | C5: Librado et al. (2021) | D5: UNIQUE | E5: Zotero title and abstract | F5: YES | G5: INCLUDE | H5: Ancient horse genomics is relevant to the group's technology and mobility questions and directly evaluates a proposed Yamnaya expansion mechanism. | I5: BACKGROUND ONLY | J5: The abstract rejects a simple link between horseback riding, Yamnaya expansion and Indo-European spread, but it does not provide human genetic evidence of Yamnaya migration. | K5: EXPLICIT | L5: TARGET-PERIOD CLAIM + LATER HORSE EXPANSION | M5: YES | N5: BACKGROUND / OPTIONAL | O5: NOT ASSESSED - BACKGROUND ONLY | P5: Background-only record was not part of this 15-paper eligibility stage.
A6: 5 | B6: 24A5ALRY | C6: Scorrano et al. (2021) | D6: UNIQUE | E6: Accessible full text | F6: YES | G6: INCLUDE | H6: The study assesses the genetic and sex-biased effects of Steppe migration on Bronze Age European populations. | I6: INCLUDE - MIGRATION | J6: Abstract directly addresses migration scale, geographic impact and male-biased Steppe ancestry in Corded Ware and Bell Beaker populations. | K6: INDIRECT | L6: DIRECT / EARLY THIRD MILLENNIUM BCE | M6: YES | N6: ADVANCE | O6: INCLUDE - MIGRATION | P6: Full text assessed; sex-bias conclusions carry explicit X-chromosome and sampling cautions.
A7: 6 | B7: Z6RYK2BV | C7: Linderholm et al. (2020) | D7: UNIQUE | E7: Accessible full text | F7: YES | G7: INCLUDE | H7: Genomic, kinship and isotope evidence informs Corded Ware population history and mobility. | I7: INCLUDE - MIGRATION | J7: Abstract reports Steppe paternal ancestry, local maternal lineages and local/non-local kinship in a Corded Ware community connected to Yamnaya. | K7: INDIRECT | L7: DIRECT / THIRD MILLENNIUM CONTEXT | M7: YES | N7: ADVANCE | O7: INCLUDE - MIGRATION | P7: Full text assessed; regional community-level evidence should not be generalized to all Corded Ware groups.
A8: 7 | B8: DHIHCURJ | C8: Lazaridis et al. (2025) - duplicate | D8: DUPLICATE | E8: DOI, title, metadata and PDF checksum | F8: NO | G8: EXCLUDE | H8: Exact duplicate of canonical collection item KZVYLCU9; removed before title/abstract screening. | I8: EXCLUDE | J8: Duplicate record; the canonical copy is screened separately. | K8: NOT ASSESSED | L8: NOT APPLICABLE | M8: YES | N8: DO NOT ADVANCE | O8: NOT APPLICABLE | P8: Exact duplicate of KZVYLCU9; no assessment performed.
A9: 8 | B9: 2DPCPNXM | C9: Furholt (2018) | D9: UNIQUE | E9: Zotero title and abstract | F9: YES | G9: INCLUDE | H9: The article critiques how aDNA migration narratives are interpreted in third-millennium European archaeology. | I9: BACKGROUND ONLY | J9: Abstract provides methodological and conceptual guidance for interpreting mobility and migration but does not present a principal new migration dataset. | K9: NONE | L9: TARGET-PERIOD METHODOLOGICAL CONTEXT | M9: YES | N9: BACKGROUND / OPTIONAL | O9: NOT ASSESSED - BACKGROUND ONLY | P9: Background-only methodological record was not part of this 15-paper eligibility stage.
A10: 9 | B10: Q2Y9FLYQ | C10: Tassi et al. (2017) | D10: UNIQUE | E10: Accessible full text | F10: YES | G10: INCLUDE | H10: Ancient DNA tests demographic relationships between Globular Amphorae groups and Pontic-steppe-related populations. | I10: INCLUDE - MIGRATION + LANGUAGE | J10: Abstract compares Steppe and Anatolian language-spread models and distinguishes cultural influence from movement of people. | K10: EXPLICIT | L10: EARLIER / CONTEXT FOR LATER TARGET-PERIOD GENE FLOW | M10: YES | N10: ADVANCE | O10: INCLUDE - MIGRATION + LANGUAGE | P10: Full text assessed; negative GAC result helps distinguish cultural influence from population movement.
A11: 10 | B11: MVP4P8Z2 | C11: Ringbauer et al. (2024) | D11: UNIQUE | E11: Accessible full text | F11: YES | G11: INCLUDE | H11: The method and application reveal close genealogical connections among ancient Eurasian populations. | I11: INCLUDE - MIGRATION | J11: Abstract reports substantial recent co-ancestry between Yamnaya and Corded Ware groups, directly informing their demographic relationship. | K11: INDIRECT | L11: DIRECT / TARGET-PERIOD RELATIONSHIP | M11: YES | N11: ADVANCE | O11: INCLUDE - MIGRATION | P11: Full text assessed; IBD supplies direct recent co-ancestry, not linguistic identity.
A12: 11 | B12: 8LBVFX2C | C12: Dzhaubermezov et al. (2026) | D12: UNIQUE | E12: Accessible full text | F12: YES | G12: INCLUDE | H12: Systematic review and meta-analysis addresses Caucasus demographic history, Steppe gene flow and Yamnaya expansion. | I12: INCLUDE - MIGRATION | J12: Abstract synthesizes Yamnaya-linked Steppe gene flow in a major Eurasian corridor; language-genetics is mentioned mainly as broader context. | K12: BACKGROUND | L12: BROAD BRONZE AGE / REQUIRES DATE-SPECIFIC EXTRACTION | M12: YES | N12: ADVANCE | O12: INCLUDE - MIGRATION | P12: Full text assessed as secondary pooled evidence; citation date metadata remains flagged.
A13: 12 | B13: KZVYLCU9 | C13: Lazaridis et al. (2025) | D13: CANONICAL IN DUPLICATE SET | E13: Accessible full text | F13: YES | G13: INCLUDE | H13: Ancient DNA reconstructs Yamnaya formation, expansion and ancestry relationships. | I13: INCLUDE - MIGRATION + LANGUAGE | J13: Abstract details migration and admixture routes preceding Yamnaya formation, the 3300 BCE expansion, and an explicit proto-Indo-Anatolian interpretation. | K13: EXPLICIT | L13: EARLIER FORMATION + DIRECT TARGET-PERIOD EXPANSION | M13: YES | N13: ADVANCE | O13: INCLUDE - MIGRATION + LANGUAGE | P13: Full text assessed; use canonical item and keep linguistic model as interdisciplinary interpretation.
... A19: 18 | B19: 6ZNHJTYH | C19: Haak et al. (2015) | D19: UNIQUE | E19: Accessible full text | F19: YES | G19: INCLUDE | H19: Genome-wide data document large migration into Europe from the Eurasian Steppe. | I19: INCLUDE - MIGRATION + LANGUAGE | J19: Abstract directly links Steppe migration evidence to support for a Steppe-origin hypothesis for some Indo-European languages. | K19: EXPLICIT | L19: DIRECT / TARGET PERIOD | M19: YES | N19: ADVANCE | O19: INCLUDE - MIGRATION + LANGUAGE | P19: Full text assessed; the paper explicitly states that aDNA cannot identify spoken language.

Sheet PRISMA Status
A1: PRISMA Stage / Metric | B1: Count | C1: Status | D1: Evidence / Formula | E1: Constraint
A2: Identification - records identified from databases | B2: UNKNOWN | C2: UNRESOLVED | D2: No historical database/export log found | E2: Do not use the Zotero collection count as a substitute
A3: Identification - records identified by other methods | B3: UNKNOWN | C3: UNRESOLVED | D3: No historical source log found | E3: Requires group documentation
A4: Observed Zotero collection records | B4: =COUNTA(Inventory!$H$2:$H$19) -> 18 | C4: OBSERVED | D4: Zotero collection audit | E4: Context only; not necessarily the identification total
A5: Duplicate records removed before screening | B5: =COUNTIF('Screening Decisions'!$D$2:$D$19,"DUPLICATE") -> 1 | C5: COMPLETE FOR COLLECTION | D5: DOI, title, metadata and PDF checksum | E5: Record remains in Zotero but is excluded from screening counts
A6: Unique records after deduplication | B6: =B4-B5 -> 17 | C6: COMPLETE FOR COLLECTION | D6: Observed records minus duplicate excess records | E6: Applies to this Zotero collection only
A7: Titles/abstracts screened | B7: =COUNTIF('Screening Decisions'!$F$2:$F$19,"YES") -> 17 | C7: COMPLETE | D7: Study-level Screening Decisions | E7: All 17 unique records had Zotero abstracts
A8: Group exclusions at title/abstract stage | B8: =COUNTIFS('Screening Decisions'!$F$2:$F$19,"YES",'Screening Decisions'!$G$2:$G$19,"EXCLUDE") -> 0 | C8: COMPLETE | D8: Study-level Screening Decisions | E8: Duplicate is counted under deduplication, not screening exclusion
A9: Group records retained after title/abstract screen | B9: =COUNTIFS('Screening Decisions'!$F$2:$F$19,"YES",'Screening Decisions'!$G$2:$G$19,"INCLUDE") -> 17 | C9: COMPLETE | D9: Study-level Screening Decisions | E9: All 17 unique records remain relevant to at least one group topic
A10: My-section records not advanced to primary full-text eligibility | B10: =COUNTIF('Screening Decisions'!$I$2:$I$19,"BACKGROUND ONLY") -> 2 | C10: COMPLETE | D10: Two background-only records | E10: Background-only is not an overall group exclusion
A11: Reports sought for primary full-text eligibility | B11: =COUNTIF('Screening Decisions'!$N$2:$N$19,"ADVANCE") -> 15 | C11: COMPLETE | D11: 15 records marked ADVANCE | E11: Formal eligibility stage for this section
A12: Reports successfully retrieved | B12: =COUNTA('Evidence Extraction'!$B$2:$B$16) -> 15 | C12: COMPLETE | D12: Accessible local PDFs represented in Evidence Extraction | E12: Retrieved is separate from eligible
A13: Reports not retrieved | B13: =B11-B12 -> 0 | C13: COMPLETE | D13: Reports sought minus reports retrieved | E13: Zero; do not combine with full-text exclusions
A14: Full-text articles assessed for eligibility | B14: =COUNTA('Evidence Extraction'!$B$2:$B$16) -> 15 | C14: COMPLETE | D14: One evidence-extraction row per assessed study | E14: 15 primary candidates
A15: Full-text articles excluded | B15: =COUNTIF('Screening Decisions'!$O$2:$O$19,"EXCLUDE") -> 0 | C15: COMPLETE | D15: Study-level Full-Text Assessment decisions | E15: Zero candidates excluded at this stage
A16: Studies finally included in my section | B16: =COUNTIF('Screening Decisions'!$O$2:$O$19,"INCLUDE - MIGRATION")+COUNTIF('Screening Decisions'!$O$2:$O$19,"INCLUDE - LANGUAGE")+COUNTIF('Screening Decisions'!$O$2:$O$19,"INCLUDE - MIGRATION + LANGUAGE") -> 15 | C16: COMPLETE | D16: Final full-text decisions | E16: 15 primary studies; 2 other group-relevant studies remain background only
A17: Unique studies retained for the overall group review | B17: =COUNTIFS('Screening Decisions'!$F$2:$F$19,"YES",'Screening Decisions'!$G$2:$G$19,"INCLUDE") -> 17 | C17: COMPLETE | D17: Title/abstract group decision | E17: My-section status is not the group status

Sheet Evidence Extraction
A1: Study | B1: Zotero Item Key | C1: DOI | D1: Region | E1: Relevant Populations / Cultures | F1: Sample Dates | G1: Samples / Data | H1: Methods | I1: Direct Genetic Result | J1: Migration Origin | K1: Migration Destination | L1: Route / Pattern | M1: Migration Chronology | N1: Demographic Evidence | O1: Author Migration Interpretation | P1: Language Relevance | Q1: Language Inference | R1: Claim Provenance | S1: Geographic / Chronological Limits | T1: Method / Design Limits | U1: Contribution to Review | V1: Full-Text Decision | W1: Key Pages / Sections | X1: Notes
A2: Wong et al. (2017) | B2: CEFW5MDT | C2: 10.1101/gr.202945.115 | D2: Western Siberia; northeastern Europe; Urals | E2: Mansi, Khanty, Nenets, Selkup and other northern Eurasian groups; published Yamnaya and other ancient comparators | F2: Modern genomes; ancient comparators include Yamnaya (~4.7–5.3 kya) | G2: 28 high-coverage modern genomes from 14 groups, 32 additional modern genomes and 46 published ancient genomes | H2: High-coverage whole-genome sequencing; PCA; TreeMix; D-statistics; admixture modelling | I2: Western Siberian groups, especially Mansi, share excess alleles with ancient eastern Europeans including Yamnaya; western Siberian-related ancestry is also detectable in northeastern Europeans. | J2: Western Siberia / Urals | K2: Northeastern and eastern Europe | L2: Westward gene flow and later contact across northern Eurasia | M2: Authors infer western Siberian input into northeastern Europe before the Yamnaya horizon, probably before ~6.6 kya. | N2: Admixture and allele-sharing; not a directly sampled Yamnaya migration transect | O2: The authors reconstruct deep Siberia–Europe interaction and caution that Mansi are not descendants of Yamnaya. | P2: BACKGROUND | Q2: Late Proto-Indo-European is contextual only; the paper makes no independent linguistic inference. | R2: Genetic statements are direct results plus author demographic interpretation; language is background attributed to cited literature. | S2: Predominantly a northern Eurasian study using modern populations; target-period movement is indirect. | T2: Ancient genomes are published comparators; direction and timing depend on population models and sparse ancient sampling. | U2: Adds contextual evidence that northern Eurasian gene flow pre-dated and overlapped the Yamnaya horizon, qualifying a simple one-way expansion narrative. | V2: INCLUDE - MIGRATION | W2: pp. 1–2, 9–12 | X2: Use as contextual migration evidence, not as a core Yamnaya-route study.
A3: Chintalapati et al. (2022) | B3: EIBGSQF3 | C3: 10.7554/eLife.77625 | D3: Europe and western Asia; 16 regional groupings | E3: Mesolithic, Neolithic, Steppe pastoralist, Yamnaya/Afanasievo-related and later European populations | F3: ~8000–350 BCE | G3: Approximately 1,100 published ancient individuals | H3: DATES ancestry-covariance dating; ancestry source modelling; regional meta-analysis | I3: Admixture-date estimates reconstruct the formation and spread of Steppe pastoralist ancestry; estimated Yamnaya/Afanasievo genetic formation precedes their archaeological appearance by more than a millennium. | J3: Pontic-Caspian Steppe and related eastern sources | K3: Multiple European regions and the Altai | L3: Multi-stage westward and eastward dispersal of Steppe ancestry | M3: Formation before the Yamnaya horizon; major dispersals around and after ~3000 BCE | N3: Dated ancestry mixture and regional shifts | O3: The authors interpret the dated admixture patterns as a reconstruction of major Holocene migrations. | P3: EXPLICIT | Q3: The demographic chronology is presented as relevant to competing models of Indo-European dispersal; DNA does not identify the language spoken. | R3: Admixture dates are direct model outputs; migration and language links are author interpretations. | S3: Very broad spatial and temporal coverage; regional sampling density is uneven and much evidence lies outside 3300–2600 BCE. | T3: DATES approximates pulse admixture; multiple pulses can yield intermediate dates, closely related sources are difficult to separate and low ancestry proportions are uncertain. | U3: Provides a comparative chronology for Steppe-related ancestry formation and its westward/eastward spread. | V3: INCLUDE - MIGRATION + LANGUAGE | W3: pp. 1–6 and regional-results sections | X3: Treat linguistic relevance as interpretation of the demographic timeline.
A4: Wang et al. (2021) | B4: 4IUR2RSU | C4: 10.1038/s41586-021-03336-2 | D4: Mongolia, northern China, Amur region and western China | E4: Yamnaya/Afanasievo-related groups, Chemurchek, Shirenzigou and other ancient East Asian populations | F4: ~6000 BCE–AD 1000 | G4: 166 ancient individuals and 383 present-day individuals from 46 groups | H4: Genome-wide capture / sequencing; PCA; qpWave; qpAdm; qpGraph; ancestry modelling | I4: Afanasievo is genetically very close to Yamnaya; Yamnaya/Afanasievo-related ancestry reached western Mongolia after ~3000 BCE, later declined there and persisted farther west in Xinjiang. | J4: Pontic-Caspian Steppe via Afanasievo-associated eastern groups | K4: Altai, western Mongolia and Xinjiang | L4: Eastward Steppe dispersal with later regional admixture and partial ancestry loss | M4: After ~3000 BCE, with later Bronze and Iron Age continuities | N4: Appearance of Yamnaya/Afanasievo-related ancestry, admixture and regional turnover | O4: The authors interpret the genetic links as evidence for movement of Yamnaya descendants into Inner Asia. | P4: EXPLICIT | Q4: The authors argue that the demographic evidence adds weight to a migration-mediated spread of proto-Tocharian; this remains an interdisciplinary inference. | R4: Ancestry estimates are direct genetic results; the Tocharian link is author interpretation. | S4: East Asian ancient-DNA sampling is uneven, with several small or singleton archaeological groups; most evidence is east of the core Yamnaya zone. | T4: Some qpAdm models are equally plausible and closely related sources can be difficult to distinguish; cultural association does not guarantee matching ancestry. | U4: Supplies the principal eastward case study and an explicit, qualified Tocharian interpretation. | V4: INCLUDE - MIGRATION + LANGUAGE | W4: pp. 1, 4–6 | X4: An Afanasievo-associated child without Yamnaya ancestry illustrates culture–ancestry non-equivalence.
A5: Scorrano et al. (2021) | B5: 24A5ALRY | C5: 10.1080/03014460.2021.1942984 | D5: Central, eastern, western and southern Europe | E5: Yamnaya proxies; Corded Ware; Bell Beaker; Neolithic and Bronze Age Europeans | F5: Late Neolithic to Bronze Age, focused on the third millennium BCE | G5: Published genome-wide and uniparental datasets; mtDNA phylogeny includes 695 samples; analysis-specific sample sizes vary | H5: PCA; qpAdm; outgroup f3; mtDNA and Y-chromosome analysis; autosome-versus-X ancestry comparison | I5: Steppe-related ancestry is highest in several Corded Ware groups and is more strongly male-biased there than in Bell Beaker groups; no comparable significant Steppe input is detected in the pooled mitochondrial gene pool. | J5: Pontic-Caspian Steppe | K5: Primarily central and eastern Europe, with weaker or heterogeneous signals farther west and south | L5: Westward, sex-biased ancestry dispersal followed by regionally variable admixture | M5: Mainly early to middle third millennium BCE | N5: High Steppe ancestry, sex-biased admixture and partial paternal-line replacement | O5: The authors interpret the autosomal, X-chromosomal and uniparental differences as predominantly male-driven migration, especially into Corded Ware groups. | P5: INDIRECT | Q5: The discussion treats Steppe ancestry as compatible with the spread of some Indo-European languages but also notes counterexamples; language is not measured. | R5: Genetic proportions are direct/modelled results; migration and language connections are author interpretation. | S5: Coverage is strongest for central/eastern Europe and varies sharply by regional archaeological group. | T5: Published-data reanalysis; low X-chromosome SNP counts and large standard deviations require caution; Yamnaya Y lineages are an imperfect male-source proxy. | U5: Provides a focused test of sex-biased migration and cautions against assuming the same demographic process across all of Europe. | V5: INCLUDE - MIGRATION | W5: pp. 1–3, 7–9 | X5: Language discussion is secondary and should not change the section classification.
A6: Linderholm et al. (2020) | B6: Z6RYK2BV | C6: 10.1038/s41598-020-63138-w | D6: Southeastern Poland: Rzeszów Foothills, Małopolska Upland and Sokal Ridge | E6: Corded Ware and Bell Beaker individuals; Neolithic local and Steppe-related ancestry components | F6: Late third millennium BCE; individual radiocarbon dates reported | G6: 19 genomes obtained from 53 sampled individuals (16 Corded Ware, 3 Bell Beaker); strontium for 16 individuals | H6: Whole-genome sequencing; PCA and ancestry analysis; mtDNA/Y haplogroups; kinship; strontium isotopes; radiocarbon dating | I6: Corded Ware individuals combine predominantly Steppe-associated paternal ancestry with maternal lineages linked to earlier Neolithic populations; three kin relationships include a local/non-local pair. | J6: Eastern Steppe-related ancestry | K6: Southeastern Poland | L6: Westward ancestry movement followed by local admixture and community-level mobility | M6: Corded Ware dominance after ~2800 BCE; sampled burials lie in the later third millennium BCE | N6: Admixture, sex-biased ancestry, kinship and isotope-based local/non-local mobility | O6: The authors interpret the combined evidence as a complex, regionally specific Corded Ware community rather than a homogeneous migrant population. | P6: INDIRECT | Q6: Linguistic change is mentioned as part of the broader third-millennium transition; no independent language analysis is performed. | R6: Genomic and isotope observations are direct results; wider migration and language statements are author interpretation/background. | S6: A single regional transect in southeastern Poland cannot represent all Corded Ware populations. | T6: Small sample size and uneven genome coverage (~0.02× to 5.47×); isotope baselines and cultural labels constrain mobility interpretation. | U6: Adds fine-scale evidence for sex-biased ancestry, local admixture and mobility within a Corded Ware community. | V6: INCLUDE - MIGRATION | W6: pp. 1–4 and Results/Discussion | X6: Useful for qualifying continent-wide replacement models with community-level complexity.
A7: Tassi et al. (2017) | B7: Q2Y9FLYQ | C7: 10.1098/rspb.2017.1540 | D7: Kierzkowo, northwestern Poland; central European comparison | E7: Globular Amphorae culture, earlier Neolithic farmers, Yamnaya/Steppe-related groups and Corded Ware | F7: GAC context before the main Steppe expansion, approximately 3400/3100–2800 BCE | G7: Six individuals with nuclear data at 597,573 SNPs and 11 complete Neolithic mitochondrial sequences | H7: Genome-wide comparison; PCA and allele-sharing statistics; mitochondrial analysis; approximate Bayesian computation of alternative demographic models | I7: Sampled GAC individuals are closer to earlier Neolithic groups than to populations related to Pontic-Steppe migration and lack the expected Yamnaya-derived profile. | J7: No supported Yamnaya-derived origin for the sampled GAC group | K7: Northwestern Poland / central Europe | L7: Local genetic continuity with eastern cultural influence, before later Steppe gene flow | M7: Immediately before and overlapping the start of the target period | N7: Continuity and absence of expected Steppe ancestry; later gene flow is not rejected | O7: The authors interpret GAC eastern archaeological affinities as cultural influence rather than movement of Steppe people. | P7: EXPLICIT | Q7: The study tests demographic expectations of Steppe/Kurgan and Anatolian language-dispersal models and stresses that language change need not track migration exactly. | R7: Genetic model comparison is direct; implications for Indo-European dispersal are author interpretation. | S7: One burial context in northwestern Poland and a small number of individuals limit geographic generalization. | T7: Small sample; preservation and sample-selection losses; demographic conclusions depend on the compared models and reference populations. | U7: Provides a negative/qualifying case showing that archaeological eastern affinity need not imply Steppe migration or linguistic identity. | V7: INCLUDE - MIGRATION + LANGUAGE | W7: pp. 1–4, 6–8 | X7: Use to separate cultural transmission from demic diffusion.
A8: Ringbauer et al. (2024) | B8: MVP4P8Z2 | C8: 10.1038/s41588-023-01582-w | D8: Eurasia, with a focused Corded Ware–Yamnaya analysis | E8: Yamnaya, Corded Ware, Globular Amphora and other Eneolithic/Bronze Age groups | F8: Broad ancient dataset; relevant Corded Ware interval ~3000–2400 BCE | G8: 4,248 ancient Eurasian individuals | H8: ancIBD hidden Markov model; GLIMPSE imputation/phasing; identity-by-descent segment analysis | I8: Corded Ware groups share long IBD segments, including segments up to 20 cM, with multiple Yamnaya groups; most Corded Ware ancestry has genealogical links to Yamnaya within at most a few hundred years, alongside a substantial GAC-related component. | J8: Pontic-Caspian Steppe plus eastern European GAC-related ancestry | K8: Eastern, central and northern European Corded Ware groups | L8: Rapid, connected westward/northward dispersal followed by admixture | M8: Gene flow beginning around 3000 BCE; relationships span only a few hundred years | N8: Recent co-ancestry, direct genealogical links and admixture | O8: The authors interpret long IBD sharing as inconsistent with a remote unsampled Steppe-like source separated from Yamnaya by about a millennium. | P8: INDIRECT | Q8: The study provides a demographic mechanism relevant to language spread but makes no independent claim about which language sampled people spoke. | R8: IBD segments are direct model outputs; migration is author interpretation; any linguistic use is later synthesis. | S8: Results depend on which ancient individuals pass coverage thresholds and on uneven archaeological sampling. | T8: Reliable detection is mainly for segments >8 cM and adequate coverage; SNP density, low coverage, imputation and false positives limit shorter-segment inference. | U8: Strengthens the immediate genealogical connection between Yamnaya and diverse Corded Ware populations. | V8: INCLUDE - MIGRATION | W8: pp. 1, 5, 7–8 | X8: No independent linguistic evidence.
A9: Dzhaubermezov et al. (2026) | B9: 8LBVFX2C | C9: 10.1016/j.biosystems.2026.105906 | D9: North and South Caucasus | E9: Caucasus hunter-gatherers, Maykop, Yamnaya, Catacomb, Kura-Araxes and later Caucasus populations | F9: ~50,000 BCE–AD 1914; Bronze Age evidence is the relevant subset | G9: 669 ancient individuals compiled; 565 ancient Caucasus individuals retained for PCA after quality control; modern comparators also used | H9: Systematic synthesis of published datasets; quality-controlled pooled reanalysis; PCA; D-statistics; relatedness screening | I9: The pooled data show early north–south differentiation, Bronze Age Steppe-related gene flow associated with Yamnaya and later admixture alongside substantial regional continuity. | J9: Eurasian Steppe and eastern Europe | K9: Caucasus populations | L9: Corridor-like, bidirectional interaction across and around the Caucasus | M9: Long-term prehistory; Yamnaya-linked signal concentrated in the Bronze Age | N9: Gene flow, admixture, differentiation and continuity | O9: The authors synthesize the Caucasus as both a barrier and migration corridor involved in the ancestry of Steppe pastoralist societies. | P9: BACKGROUND | Q9: Proto-Indo-Anatolian and language–genetics links are largely attributed to recent cited studies rather than independently tested. | R9: Pooled genetic patterns are reanalysis results; many detailed migration and language claims are synthesis or attribution to source studies. | S9: Extremely broad chronology; early North Caucasus and late historical sampling gaps; Bronze Age findings must be isolated from later continuity. | T9: Secondary data vary in coverage, laboratory pipelines and sampling; pooled PCA is descriptive; source-study overlap risks double counting. | U9: Provides Caucasus corridor context and a secondary cross-study check on Steppe-related gene flow. | V9: INCLUDE - MIGRATION | W9: pp. 1–4 and Bronze Age/Conclusion sections | X9: Zotero issue-date metadata is later than the audit date and remains flagged for citation verification.
A10: Lazaridis et al. (2025) | B10: KZVYLCU9 | C10: 10.1038/s41586-024-08531-5 | D10: Caucasus–Lower Volga, Volga, Dnipro, Pontic-Caspian Steppe and southeast Europe | E10: Caucasus–Lower Volga cline, Volga cline, Dnipro cline, Serednii Stih, Yamnaya, Corded Ware and Anatolian-related groups | F10: ~6400–2000 BCE | G10: 435 individuals (367 newly reported plus 68 with improved data); 803 libraries screened | H10: Genome-wide ancient DNA; PCA; qpWave/qpAdm competition framework; admixture dating; IBD and haplogroup analyses | I10: Caucasus–Lower Volga ancestry moved west and mixed with Dnipro/Don hunter-gatherer ancestry, contributing about four-fifths of Yamnaya ancestry; a Core Yamnaya population formed by ~4000 BCE and expanded rapidly after ~3300 BCE. | J10: Caucasus–Lower Volga and lower Dnipro/Don interaction zone | K10: Pontic-Caspian Steppe, Danube corridor, southeastern Europe and east to Kazakhstan | L10: Multi-stage formation followed by rapid westward and eastward expansion | M10: Precursors ~4500–4000 BCE; Yamnaya expansion after ~3300 BCE | N10: Admixture, ancestry clines, rapid demographic expansion and later local admixture | O10: The authors propose a lower Dnipro/Don-centred formation process and a rapid Yamnaya expansion, while acknowledging unresolved core geography. | P10: EXPLICIT | Q10: The authors propose proto-Indo-Anatolian unity among Caucasus–Lower Volga populations before Yamnaya formation and link later dispersals to language branching. | R10: Ancestry models are direct genetic results; migration routes and proto-Indo-Anatolian reconstruction are interdisciplinary author interpretations. | S10: More than 80% of the study samples are from Russia; lower Volga precursors and some proposed routes remain sparsely sampled. | T10: An unsampled CHG-related source is required in models; precise Anatolian route/source and Core Yamnaya location cannot be fixed conclusively. | U10: Provides the central formation-and-expansion model and the collection's strongest explicit genetics–language synthesis. | V10: INCLUDE - MIGRATION + LANGUAGE | W10: pp. 1–7 | X10: Use the canonical Zotero item; DHIHCURJ is an exact duplicate.
A11: Nikitin et al. (2025) | B11: 9DJYHJ7E | C11: 10.1038/s41586-024-08372-2 | D11: North Pontic region, especially present-day Ukraine | E11: North Pontic foragers, Trypillian farmers, Usatove, Serednii Stih and Yamna | F11: Neolithic to Early Bronze Age; key interval ~4500–3300 BCE | G11: 81 prehistoric North Pontic individuals; 51 direct radiocarbon dates; co-analysis with the companion Steppe dataset | H11: Genome-wide ancient DNA; PCA; qpAdm/ancestry modelling; radiocarbon and isotope context | I11: Three ancestry-bearing movements are resolved: Caucasus–Lower Volga migrants mixing with Trypillians to form Usatove, a parallel mixture with foragers forming Serednii Stih, and Yamna descent from Serednii Stih with expansion from ~3300 BCE. | J11: Caucasus–Lower Volga and North Pontic interaction zones | K11: Usatove/North Pontic sites and then wider Eurasia | L11: Successive westward/local mixtures followed by Yamna expansion | M11: ~4500 BCE, ~4000 BCE formation, and ~3300 BCE expansion | N11: Admixture, ancestry replacement and repeated incorporation of outsiders | O11: The authors interpret the three waves as a flexible demographic strategy underlying Yamna success and expansion. | P11: INDIRECT | Q11: Indo-European dispersal is contextual; the paper reconstructs a plausible population mechanism but does not directly identify language. | R11: Genetic mixtures are direct/modelled results; migration-wave framing is author interpretation; language link is contextual. | S11: Concentrated in the North Pontic region and dependent on site availability; the wider Eurasian expansion is inferred using companion data. | T11: Some proximate ancestry sources remain unclear; uneven earlier sampling and model dependence limit fine-scale route certainty. | U11: Supplies high-resolution evidence for Yamnaya formation immediately before, and expansion at the start of, the target period. | V11: INCLUDE - MIGRATION | W11: pp. 1–4 and Discussion | X11: Mykhailivka individual (3635–3383 BCE) bridges the Serednii Stih–Yamna temporal gap.
A12: Papac et al. (2021) | B12: U92TYDRN | C12: 10.1126/sciadv.abi6941 | D12: Bohemia, central Europe | E12: Pre-Corded Ware groups, Corded Ware, Bell Beaker and Únětice populations | F12: ~4900–1600 BCE; key evidence ~2900–2400 BCE | G12: 271 ancient human genomes | H12: Genome-wide ancient DNA; PCA; f-statistics/qpAdm; haplogroups; kinship and temporal population modelling | I12: Corded Ware appears by ~2900 BCE with high but heterogeneous Steppe ancestry not wholly derived from sampled Yamnaya; diverse females were assimilated, followed by sharp Y-chromosome changes around 2600 and 2400 BCE and later ≥40% turnover. | J12: Eastern Steppe-related sources and local central European groups | K12: Bohemia | L12: Westward arrival followed by local assimilation and repeated social/genetic reorganization | M12: ~2900 BCE arrival; transformations around 2600 and 2400 BCE; later Bronze Age turnover | N12: Migration, admixture, sex-biased incorporation and partial population replacement | O12: The authors interpret the Bohemian transect as evidence for multiple migrations and changing social structures, not a single homogeneous replacement. | P12: INDIRECT | Q12: The population movements could carry language, but the study does not independently determine linguistic identity. | R12: Genetic changes are direct/modelled results; migration and social implications are author interpretation; any language connection is later synthesis. | S12: One central-European region; later 2400 BCE and Bronze Age evidence lies outside the primary 3300–2600 BCE interval. | T12: Archaeological culture labels may not represent unified social entities; source populations remain partly unsampled and ancestry models are proxy-dependent. | U12: Provides a regional time transect that qualifies simple mass-replacement and single-source accounts. | V12: INCLUDE - MIGRATION | W12: pp. 1–6 | X12: Clearly label post-2600 BCE results as later consequences.
... A16: Haak et al. (2015) | B16: 6ZNHJTYH | C16: 10.1038/nature14317 | D16: Central and northern Europe with Yamnaya samples from Samara | E16: Yamnaya, Corded Ware, Late Neolithic/Early Bronze Age Europeans and earlier farmers/hunter-gatherers | F16: Mainly ~6000–1000 BCE; key Yamnaya/Corded Ware comparison ~3300–2500 BCE | G16: 69 newly analysed ancient Europeans (94 libraries); combined analysis includes 25 previously published ancient individuals | H16: 390,000-SNP capture; PCA; ADMIXTURE; f3/f4 statistics; ancestry modelling; mtDNA and Y haplogroups | I16: German Corded Ware individuals derive roughly three-quarters of their ancestry from a Yamnaya-related source, indicating a rapid and large population influx from the eastern Steppe around the early third millennium BCE. | J16: Pontic-Caspian Steppe / Samara-related source | K16: Central Europe and farther west/north | L16: Rapid westward migration and admixture with local Neolithic populations | M16: Approximately 3000–2500 BCE | N16: Large ancestry turnover, admixture and participation of both sexes | O16: The authors interpret the ancestry shift as evidence for a major migration from the Steppe into central Europe. | P16: EXPLICIT | Q16: The demographic migration is presented as supporting a Steppe-origin model for at least some Indo-European languages; the paper explicitly notes that ancient DNA is silent on language itself. | R16: Ancestry proportions are direct/modelled results; the Indo-European connection is author interpretation. | S16: Samara Yamnaya may not be the direct source population; southern-European and Asian language histories are not resolved. | T16: Small group sizes, uneven coverage and proxy-source choice limit exact route and ancestry estimates. | U16: Foundational evidence for large-scale westward Steppe migration and a carefully qualified demographic–linguistic interpretation. | V16: INCLUDE - MIGRATION + LANGUAGE | W16: pp. 1–4 | X16: Preserve the authors' explicit statement that DNA cannot reveal spoken language.

Sheet Synthesis Table
A1: Study | B1: Analytical Theme | C1: Analytical Role | D1: Region | E1: Date / Samples | F1: Methods | G1: Genetic / Demographic Result | H1: Migration Evidence | I1: Route / Pattern | J1: Connected Populations | K1: Migration Chronology | L1: Language Relevance | M1: Language Interpretation | N1: Main Interpretation | O1: Limitations | P1: Contribution to Review | Q1: Zotero Item Key | R1: Evidence Pointer
A2: ='Evidence Extraction'!A10 -> Lazaridis et al. (2025) | B2: Yamnaya formation and launch | C2: CORE | D2: ='Evidence Extraction'!D10 -> Caucasus–Lower Volga, Volga, Dnipro, Pontic-Caspian Steppe and southeast Europe | E2: ='Evidence Extraction'!F10&" | "&'Evidence Extraction'!G10 -> ~6400–2000 BCE | 435 individuals (367 newly reported plus 68 with improved data); 803 libraries screened | F2: ='Evidence Extraction'!H10 -> Genome-wide ancient DNA; PCA; qpWave/qpAdm competition framework; admixture dating; IBD and haplogroup analyses | G2: ='Evidence Extraction'!I10 -> Caucasus–Lower Volga ancestry moved west and mixed with Dnipro/Don hunter-gatherer ancestry, contributing about four-fifths of Yamnaya ancestry; a Core Yamnaya population formed by ~4000 BCE and expanded rapidly after ~3300 BCE. | H2: CLV ancestry moved west and mixed with Dnipro/Don-related ancestry to form the dominant ancestry of Yamnaya; expansion follows at about 3300 BCE. | I2: ='Evidence Extraction'!L10 -> Multi-stage formation followed by rapid westward and eastward expansion | J2: ='Evidence Extraction'!E10 -> Caucasus–Lower Volga cline, Volga cline, Dnipro cline, Serednii Stih, Yamnaya, Corded Ware and Anatolian-related groups | K2: ='Evidence Extraction'!M10 -> Precursors ~4500–4000 BCE; Yamnaya expansion after ~3300 BCE | L2: ='Evidence Extraction'!P10 -> EXPLICIT | M2: ='Evidence Extraction'!Q10 -> The authors propose proto-Indo-Anatolian unity among Caucasus–Lower Volga populations before Yamnaya formation and link later dispersals to language branching. | N2: ='Evidence Extraction'!O10 -> The authors propose a lower Dnipro/Don-centred formation process and a rapid Yamnaya expansion, while acknowledging unresolved core geography. | O2: ='Evidence Extraction'!S10&" | "&'Evidence Extraction'!T10 -> More than 80% of the study samples are from Russia; lower Volga precursors and some proposed routes remain sparsely sampled. | An unsampled CHG-related source is required in models; precise Anatolian route/source and Core Yamnaya location cannot be fixed conclusively. | P2: ='Evidence Extraction'!U10 -> Provides the central formation-and-expansion model and the collection's strongest explicit genetics–language synthesis. | Q2: ='Evidence Extraction'!B10 -> KZVYLCU9 | R2: ="Evidence Extraction row 10; "&'Evidence Extraction'!W10 -> Evidence Extraction row 10; pp. 1–7
A3: ='Evidence Extraction'!A11 -> Nikitin et al. (2025) | B3: Yamnaya formation and launch | C3: CORE | D3: ='Evidence Extraction'!D11 -> North Pontic region, especially present-day Ukraine | E3: ='Evidence Extraction'!F11&" | "&'Evidence Extraction'!G11 -> Neolithic to Early Bronze Age; key interval ~4500–3300 BCE | 81 prehistoric North Pontic individuals; 51 direct radiocarbon dates; co-analysis with the companion Steppe dataset | F3: ='Evidence Extraction'!H11 -> Genome-wide ancient DNA; PCA; qpAdm/ancestry modelling; radiocarbon and isotope context | G3: ='Evidence Extraction'!I11 -> Three ancestry-bearing movements are resolved: Caucasus–Lower Volga migrants mixing with Trypillians to form Usatove, a parallel mixture with foragers forming Serednii Stih, and Yamna descent from Serednii Stih with expansion from ~3300 BCE. | H3: Three successive migration/admixture waves connect CLV migrants, Usatove, Serednii Stih and the eventual Yamna expansion. | I3: ='Evidence Extraction'!L11 -> Successive westward/local mixtures followed by Yamna expansion | J3: ='Evidence Extraction'!E11 -> North Pontic foragers, Trypillian farmers, Usatove, Serednii Stih and Yamna | K3: ='Evidence Extraction'!M11 -> ~4500 BCE, ~4000 BCE formation, and ~3300 BCE expansion | L3: ='Evidence Extraction'!P11 -> INDIRECT | M3: ='Evidence Extraction'!Q11 -> Indo-European dispersal is contextual; the paper reconstructs a plausible population mechanism but does not directly identify language. | N3: ='Evidence Extraction'!O11 -> The authors interpret the three waves as a flexible demographic strategy underlying Yamna success and expansion. | O3: ='Evidence Extraction'!S11&" | "&'Evidence Extraction'!T11 -> Concentrated in the North Pontic region and dependent on site availability; the wider Eurasian expansion is inferred using companion data. | Some proximate ancestry sources remain unclear; uneven earlier sampling and model dependence limit fine-scale route certainty. | P3: ='Evidence Extraction'!U11 -> Supplies high-resolution evidence for Yamnaya formation immediately before, and expansion at the start of, the target period. | Q3: ='Evidence Extraction'!B11 -> 9DJYHJ7E | R3: ="Evidence Extraction row 11; "&'Evidence Extraction'!W11 -> Evidence Extraction row 11; pp. 1–4 and Discussion
